Workbook

Sheet LGU FORM A by Country
A1: FORM A
A3: Region: ______
A4: ______________________________
A5: (Month, Year)
A7: REPORT ON THE REGIONAL DISTRIBUTION OF TRAVELERS
A10: City/Municipality: | B10: _________________________________________
A11: Province: | B11: _________________________________________
A13: COUNTRY OF RESIDENCE | B13: AE 1 | C13: AE 2 | D13: AE 3 | E13: AE 4 | F13: AE # | G13: AE # | H13: AE # | I13: AE # | J13: AE # | K13: AE # | L13: AE # | M13: AE # | N13: AE # | O13: AE # | P13: AE # | Q13: AE # | R13: AE # | S13: AE # | T13: AE # | U13: AE # | V13: AE # | W13: AE # | X13: AE # | Y13: TOTAL
A15: PHILIPPINE RESIDENTS
A16: FILIPINO NATIONALITY | Y16: =SUM(B16:X16) -> 0
A17: FOREIGN NATIONALITY | B17: =B137 -> 2 | C17: =C137 -> 0 | D17: =D137 -> 0 | E17: =E137 -> 0 | F17: =F137 -> 0 | G17: =G137 -> 0 | H17: =H137 -> 0 | I17: =I137 -> 0 | ... X17: =X137 -> 0 | Y17: =SUM(B17:X17) -> 2
A18: TOTAL PHILIPPINE RESIDENTS | B18: =SUM(B16:B17) -> 2 | C18: =SUM(C16:C17) -> 0 | D18: =SUM(D16:D17) -> 0 | E18: =SUM(E16:E17) -> 0 | F18: =SUM(F16:F17) -> 0 | G18: =SUM(G16:G17) -> 0 | H18: =SUM(H16:H17) -> 0 | I18: =SUM(I16:I17) -> 0 | ... X18: =SUM(X16:X17) -> 0 | Y18: =SUM(B18:X18) -> 2
A20: NON-PHILIPPINE RESIDENTS
A22: ASIA
A23: ASEAN
A24: BRUNEI | Y24: =SUM(B24:X24) -> 0
A25: CAMBODIA | B25: 1 | Y25: =SUM(B25:X25) -> 1
A26: INDONESIA | Y26: =SUM(B26:X26) -> 0
A27: LAOS | Y27: =SUM(B27:X27) -> 0
A28: MALAYSIA | Y28: =SUM(B28:X28) -> 0
A29: MYANMAR | Y29: =SUM(B29:X29) -> 0
A30: SINGAPORE | Y30: =SUM(B30:X30) -> 0
A31: THAILAND | Y31: =SUM(B31:X31) -> 0
A32: VIETNAM | Y32: =SUM(B32:X32) -> 0
A33: SUB-TOTAL | B33: =SUM(B24:B32) -> 1 | C33: =SUM(C24:C32) -> 0 | D33: =SUM(D24:D32) -> 0 | E33: =SUM(E24:E32) -> 0 | F33: =SUM(F24:F32) -> 0 | G33: =SUM(G24:G32) -> 0 | H33: =SUM(H24:H32) -> 0 | I33: =SUM(I24:I32) -> 0 | ... X33: =SUM(X24:X32) -> 0 | Y33: =SUM(B33:X33) -> 1
A35: EAST ASIA
A36: CHINA | Y36: =SUM(B36:X36) -> 0
A37: HONGKONG | Y37: =SUM(B37:X37) -> 0
A38: JAPAN | Y38: =SUM(B38:X38) -> 0
A39: KOREA | B39: 1 | Y39: =SUM(B39:X39) -> 1
A40: MACAU* | Y40: =SUM(B40:X40) -> 0
A41: TAIWAN | Y41: =SUM(B41:X41) -> 0
A42: SUB-TOTAL | B42: =SUM(B36:B41) -> 1 | C42: =SUM(C36:C41) -> 0 | D42: =SUM(D36:D41) -> 0 | E42: =SUM(E36:E41) -> 0 | F42: =SUM(F36:F41) -> 0 | G42: =SUM(G36:G41) -> 0 | H42: =SUM(H36:H41) -> 0 | I42: =SUM(I36:I41) -> 0 | ... X42: =SUM(X36:X41) -> 0 | Y42: =SUM(B42:X42) -> 1
A44: SOUTH ASIA
A45: BANGLADESH | Y45: =SUM(B45:X45) -> 0
A46: INDIA | Y46: =SUM(B46:X46) -> 0
A47: IRAN | Y47: =SUM(B47:X47) -> 0
A48: NEPAL | Y48: =SUM(B48:X48) -> 0
A49: PAKISTAN | Y49: =SUM(B49:X49) -> 0
A50: SRI LANKA | Y50: =SUM(B50:X50) -> 0
...

Sheet LGU FORM A (Sum) by Country
A1: FORM A
A3: Region: ______
A4: ______________________________
A5: (Month, Year)
A7: REPORT ON THE REGIONAL DISTRIBUTION OF TRAVELERS
A10: City/Municipality:
A11: Province:
A13: COUNTRY OF RESIDENCE | B13: TOTAL
A15: PHILIPPINE RESIDENTS
A16: FILIPINO NATIONALITY | B16: ='LGU FORM A by Country'!Y16 -> 0
A17: FOREIGN NATIONALITY | B17: ='LGU FORM A by Country'!Y17 -> 2
A18: TOTAL PHILIPPINE RESIDENTS | B18: ='LGU FORM A by Country'!Y18 -> 2
A20: NON-PHILIPPINE RESIDENTS
A22: ASIA
A23: ASEAN
A24: BRUNEI | B24: ='LGU FORM A by Country'!Y24 -> 0
A25: CAMBODIA | B25: ='LGU FORM A by Country'!Y25 -> 1
A26: INDONESIA | B26: ='LGU FORM A by Country'!Y26 -> 0
A27: LAOS | B27: ='LGU FORM A by Country'!Y27 -> 0
A28: MALAYSIA | B28: ='LGU FORM A by Country'!Y28 -> 0
A29: MYANMAR | B29: ='LGU FORM A by Country'!Y29 -> 0
A30: SINGAPORE | B30: ='LGU FORM A by Country'!Y30 -> 0
A31: THAILAND | B31: ='LGU FORM A by Country'!Y31 -> 0
A32: VIETNAM | B32: ='LGU FORM A by Country'!Y32 -> 0
A33: SUB-TOTAL | B33: ='LGU FORM A by Country'!Y33 -> 1
A35: EAST ASIA
A36: CHINA | B36: ='LGU FORM A by Country'!Y36 -> 0
A37: HONGKONG | B37: ='LGU FORM A by Country'!Y37 -> 0
A38: JAPAN | B38: ='LGU FORM A by Country'!Y38 -> 0
A39: KOREA | B39: ='LGU FORM A by Country'!Y39 -> 1
A40: MACAU* | B40: ='LGU FORM A by Country'!Y40 -> 0
A41: TAIWAN | B41: ='LGU FORM A by Country'!Y41 -> 0
A42: SUB-TOTAL | B42: ='LGU FORM A by Country'!Y42 -> 1
A44: SOUTH ASIA
A45: BANGLADESH | B45: ='LGU FORM A by Country'!Y45 -> 0
A46: INDIA | B46: ='LGU FORM A by Country'!Y46 -> 0
A47: IRAN | B47: ='LGU FORM A by Country'!Y47 -> 0
A48: NEPAL | B48: ='LGU FORM A by Country'!Y48 -> 0
A49: PAKISTAN | B49: ='LGU FORM A by Country'!Y49 -> 0
A50: SRI LANKA | B50: ='LGU FORM A by Country'!Y50 -> 0
...

Sheet LGU FORM A by Country (Monthly)
A1: DAE3. FORM A
A3: Region: ______
A4: ______________________________
A5: (Month, Year)
A7: REPORT ON THE REGIONAL DISTRIBUTION OF TRAVELERS
A10: City/Municipality: | B10: _________________________________________
A11: Province: | B11: _________________________________________
A13: COUNTRY OF RESIDENCE | B13: January | C13: February | D13: March | E13: April | F13: May | G13: June | H13: July | I13: August | J13: September | K13: October | L13: November | M13: December | N13: TOTAL
A15: PHILIPPINE RESIDENTS
A16: FILIPINO NATIONALITY | N16: =SUM(B16:M16) -> 0
A17: FOREIGN NATIONALITY | N17: =SUM(B17:M17) -> 0
A18: TOTAL PHILIPPINE RESIDENTS | B18: =SUM(B16:B17) -> 0 | C18: =SUM(C16:C17) -> 0 | D18: =SUM(D16:D17) -> 0 | E18: =SUM(E16:E17) -> 0 | F18: =SUM(F16:F17) -> 0 | G18: =SUM(G16:G17) -> 0 | H18: =SUM(H16:H17) -> 0 | I18: =SUM(I16:I17) -> 0 | ... M18: =SUM(M16:M17) -> 0 | N18: =SUM(B18:M18) -> 0
A20: NON-PHILIPPINE RESIDENTS
A22: ASIA
A23: ASEAN
A24: BRUNEI | N24: =SUM(B24:M24) -> 0
A25: CAMBODIA | N25: =SUM(B25:M25) -> 0
A26: INDONESIA | N26: =SUM(B26:M26) -> 0
A27: LAOS | N27: =SUM(B27:M27) -> 0
A28: MALAYSIA | N28: =SUM(B28:M28) -> 0
A29: MYANMAR | N29: =SUM(B29:M29) -> 0
A30: SINGAPORE | N30: =SUM(B30:M30) -> 0
A31: THAILAND | N31: =SUM(B31:M31) -> 0
A32: VIETNAM | N32: =SUM(B32:M32) -> 0
A33: SUB-TOTAL | B33: =SUM(B24:B32) -> 0 | C33: =SUM(C24:C32) -> 0 | D33: =SUM(D24:D32) -> 0 | E33: =SUM(E24:E32) -> 0 | F33: =SUM(F24:F32) -> 0 | G33: =SUM(G24:G32) -> 0 | H33: =SUM(H24:H32) -> 0 | I33: =SUM(I24:I32) -> 0 | ... M33: =SUM(M24:M32) -> 0 | N33: =SUM(B33:M33) -> 0
A35: EAST ASIA
A36: CHINA | N36: =SUM(B36:M36) -> 0
A37: HONGKONG | N37: =SUM(B37:M37) -> 0
A38: JAPAN | N38: =SUM(B38:M38) -> 0
A39: KOREA | N39: =SUM(B39:M39) -> 0
A40: MACAU* | N40: =SUM(B40:M40) -> 0
A41: TAIWAN | N41: =SUM(B41:M41) -> 0
A42: SUB-TOTAL | B42: =SUM(B36:B41) -> 0 | C42: =SUM(C36:C41) -> 0 | D42: =SUM(D36:D41) -> 0 | E42: =SUM(E36:E41) -> 0 | F42: =SUM(F36:F41) -> 0 | G42: =SUM(G36:G41) -> 0 | H42: =SUM(H36:H41) -> 0 | I42: =SUM(I36:I41) -> 0 | ... M42: =SUM(M36:M41) -> 0 | N42: =SUM(B42:M42) -> 0
A44: SOUTH ASIA
A45: BANGLADESH | N45: =SUM(B45:M45) -> 0
A46: INDIA | N46: =SUM(B46:M46) -> 0
A47: IRAN | N47: =SUM(B47:M47) -> 0
A48: NEPAL | N48: =SUM(B48:M48) -> 0
A49: PAKISTAN | N49: =SUM(B49:M49) -> 0
A50: SRI LANKA | N50: =SUM(B50:M50) -> 0
...
